Workbook
Name ComisiónV: Comisiones!$A$34:$A$38
Name ComisiónAs: AsigTotalPTC!$A$14:$A$31
Name ComisiónAs: Comisiones!$A$14:$A$31
Name ComisiónV: Comisiones!$A$34:$A$38
Name ComisiónUNSIS: Comisiones!$A$4:$A$11
Name ComisiónV: Comisiones!$A$34:$A$38
Name ComisiónViceRectoríaAcadémica: Comisiones!$A$36:$A$38
Name ComisiónAsignaciónConsejoAcadémico: Comisiones!$A$16:$A$29
Name ComisiónAc: Comisiones!$A$62:$A$68
Name Coordinación_del_Curso_de_Computación_para_Niños_de_Educación_Básica: Comisiones!$A$59
Name ComisiónACA: Comisiones!$A$16:$A$29
Name ComisiónAs: Comisiones!$A$14:$A$31
Name ComisiónU: Comisiones!$A$2:$A$11
Name ApoyoActividades: Comisiones!$A$64:$A$67
Name ComisiónVRA: Comisiones!$A$36:$A$38
Name ComisiónD: Comisiones!$A$51:$A$54
Name ComisiónU: Comisiones!$A$2:$A$11
Name ComisiónAc: Comisiones!$A$62:$A$68
Name ComisiónJefaturaCarreraDEP: Comisiones!$A$43:$A$45
Name ComisiónD: AsigTotalPTC!$A$51:$A$54
Name ComisiónP: Comisiones!$A$57:$A$59
Name ComisióndeViceRectoríaAcadémica: Comisiones!$A$36:$A$38
Name Comisión_de_Personal_Académico: Comisiones!$A$16:$A$29
Name ComisiónJ: AsigTotalPTC!$A$41:$A$48
Name ComisiónU: Comisiones!$A$2:$A$11
Name ComisiónP: AsigTotalPTC!$A$57:$A$59
Name ComisiónJ: Comisiones!$A$41:$A$48
Name ComisiónAc: AsigTotalPTC!$A$62:$A$68
Name ComisiónAc: Comisiones!$A$62:$A$68
Name ComisiónP: Comisiones!$A$57:$A$59
Name ComisiónDirecciónInstituto: Comisiones!$A$53:$A$54
Name ComisiónD: Comisiones!$A$51:$A$54
Name ComisiónD: Comisiones!$A$51:$A$54
Name ComisiónU: AsigTotalPTC!$A$2:$A$11
Name ComisiónAs: Comisiones!$A$14:$A$31
Name ComisiónJ: Comisiones!$A$41:$A$48
Name ComisiónoAsignacióndelConsejoAcadémico: Comisiones!$A$16:$A$29
Name ComisiónV: AsigTotalPTC!$A$34:$A$38
Name ComisiónP: Comisiones!$A$57:$A$59
Name ComisiónJ: Comisiones!$A$41:$A$48

Sheet LCB
A1: ASIGNACIÓN DE MATERIAS PARA EL SEMESTRE 26-27A
B2: Materia | C2: Profesor asignado | D2: PE-Adscripción | E2: Horas por semana | F2: Número de alumnos
B3: 116-A
B4: Química General | C4: M.B.E. Raúl Misael Cortés Olivera | D4: LCB | E4: 6
B5: Biología Celular | C5: M.B.E. Ruth Monserrat Rodríguez Hernández | D5: LCB | E5: 6
B6: Matemáticas | C6: M.C. Mónica Pérez Meza | D6: LI | E6: 5
B7: Introducción a la Metodología de la Investigación | C7: Dra. Karla Esmeralda Tello Ortega | D7: LCB | E7: 4
B8: Historia del Pensamiento Filosófico | C8: Mtro. Diego Toto Jiménez | D8: LAP | E8: 4
B10: 116-B
B11: Química General | C11: Dr. Edgar Rodrigo Guzmán Bautista | D11: LCB | E11: 6
B12: Biología Celular | C12: M.B.E. Ruth Monserrat Rodríguez Hernández | D12: LCB | E12: 6
B13: Matemáticas | C13: Dr. Amando Alejandro Ruiz Figueroa | D13: LI | E13: 5
B14: Introducción a la Metodología de la Investigación | C14: Dra. Victoria Vera Pineda | D14: LCB | E14: 4
B15: Historia del Pensamiento Filosófico | C15: M.F. Araceli Luz Alva Rodríguez Martínez | D15: LAP | E15: 4
B17: 316-A
B18: Bioquímica Metabólica | C18: Dra. Claudia Chávez López | D18: LCB | E18: 6
B19: Anatomía | C19: PTC3-LM | E19: 5
B20: Histología | C20: Dra. Melisa Karina Chacón Lázaro | D20: LCB | E20: 6
B21: Bioseguridad | C21: Dra. Victoria Vera Pineda | D21: LCB | E21: 4
B22: TIC Aplicadas a las Ciencias Biomédicas | C22: Dra. Aidee Cruz Barragán | D22: LI | E22: 4
B24: 316-B
B25: Bioquímica Metabólica | C25: Dra. Claudia Chávez López | D25: LCB | E25: 6
B26: Anatomía | C26: PTC3-LM | E26: 5
B27: Histología | C27: Dra. Melisa Karina Chacón Lázaro | D27: LCB | E27: 5
B28: Bioseguridad | C28: M.C.I.B. Ericay Berenice Martínez Ramos | D28: LCB | E28: 5
B29: TIC Aplicadas a las Ciencias Biomédicas | C29: M.T.C.A. Rolando Pedro Gabriel | D29: LI | E29: 4
B31: 516
B32: Inmunología I | C32: Dr. Edgar Rodrigo Guzmán Bautista | D32: LCB | E32: 5
B33: Fisiología Sistémica | E33: 5
B34: Bacteriología | C34: Dra. Melisa Karina Chacón Lázaro | D34: LCB | E34: 6
B35: Biología Molecular de los Eucariontes | C35: Dr. Juan Carlos Barragán Gálvez | D35: LCB | E35: 6 | G35: colocar un dia con 4 horas seguidas de esta materia
B36: Modelos de Investigación | C36: M.B.E. Diego Sait Cruz Hernández | D36: LCB | E36: 4
B41: Bioinformatica Básica
C47: PROFESORES DE LCB | D47: TOTAL DE MATERIAS | E47: Otras carreras | F47: Total Grupos | G47: Total alumnos | H47: Total horas a la semana | I47: Status | J47: Reincorporación | K47: Horario Laboral | L47: Observaciones
B48: 1 | C48: M.B.E. Raúl Misael Cortés Olivera | D48: =COUNTIF($C$4:$C$44,C48) -> 1 | E48: ='Asignación-Profesor'!D3-D48 -> 0 | F48: ='Asignación-Profesor'!D3 -> 1 | G48: ='Asignación-Profesor'!P3 -> 0 | H48: ='Asignación-Profesor'!Q3 -> 6 | K48: 9:00-14:00 y 16:00-19:00
B49: 2 | C49: M.C.C.A.R.B. Guilibaldo Gabriel Zurita Vásquez | D49: =COUNTIF($C$4:$C$44,C49) -> 0 | E49: ='Asignación-Profesor'!D4-D49 -> 3 | F49: ='Asignación-Profesor'!D4 -> 3 | G49: ='Asignación-Profesor'!P4 -> 126 | H49: ='Asignación-Profesor'!Q4 -> 18 | K49: 8:00-13:00 y 16:00-19:00
B50: 3 | C50: M.C.I.B. Ericay Berenice Martínez Ramos | D50: =COUNTIF($C$4:$C$44,C50) -> 1 | E50: ='Asignación-Profesor'!D5-D50 -> 3 | F50: ='Asignación-Profesor'!D5 -> 4 | G50: ='Asignación-Profesor'!P5 -> 0 | H50: ='Asignación-Profesor'!Q5 -> 23 | K50: 8:00-13:00 y 16:00-19:00
B51: 4 | C51: Dra. Claudia Chávez López | D51: =COUNTIF($C$4:$C$44,C51) -> 2 | E51: ='Asignación-Profesor'!D6-D51 -> 2 | F51: ='Asignación-Profesor'!D6 -> 4 | G51: ='Asignación-Profesor'!P6 -> 0 | H51: ='Asignación-Profesor'!Q6 -> 22 | K51: 8:00-13:00 y 16:00-19:00
B52: 5 | C52: M.C. Andrea Itayetzzi Ortiz García | D52: =COUNTIF($C$4:$C$44,C52) -> 0 | E52: ='Asignación-Profesor'!D7-D52 -> 4 | F52: ='Asignación-Profesor'!D7 -> 4 | G52: ='Asignación-Profesor'!P7 -> 0 | H52: ='Asignación-Profesor'!Q7 -> 21 | K52: 8:00-13:00 y 16:00-19:00 | L52: Proyecto
B53: 6 | C53: Dr. Abisaí Martínez Sánchez | D53: =COUNTIF($C$4:$C$44,C53) -> 0 | E53: ='Asignación-Profesor'!D8-D53 -> 4 | F53: ='Asignación-Profesor'!D8 -> 4 | G53: ='Asignación-Profesor'!P8 -> 0 | H53: ='Asignación-Profesor'!Q8 -> 23 | K53: 9:00-14:00 y 16:00-19:00
...

Sheet LM
A1: Dr. Juan Carlos Barragán Gálvez
B2: Materia | C2: Profesor asignado | D2: PE-Adscripción | E2: Horas por semana | F2: Número de alumnos
B3: 114-A (1)
B4: Anatomía Humana I | C4: PTC3-LM | D4: LM | E4: 6 | F4: 35
B5: Histología I | C5: Dr. Alejandro Francisco Cruz | D5: LM | E5: 5 | F5: 35
B6: Bioquímica | C6: M.B.E. Ruth Monserrat Rodríguez Hernández | D6: LCB | E6: 6 | F6: 35
B7: Embriología | C7: PTC8-LM | D7: LM | E7: 5 | F7: 35
B8: Historia del Pensamiento Filosófico | C8: M.F. Araceli Luz Alva Rodríguez Martínez | D8: LCE | E8: 4 | F8: 35
B10: 114-B (2)
B11: Anatomía Humana I | C11: PTC3-LM | D11: LM | E11: 6 | F11: 35
B12: Histología I | C12: Dr. Alejandro Francisco Cruz | D12: LM | E12: 5 | F12: 35
B13: Bioquímica | C13: Dr. Juan Carlos Barragán Gálvez | D13: LCB | E13: 6 | F13: 35
B14: Embriología | C14: PTC8-LM | D14: LM | E14: 5 | F14: 35
B15: Historia del Pensamiento Filosófico | C15: M.F. Araceli Luz Alva Rodríguez Martínez | D15: LCE | E15: 4 | F15: 35
B17: 114-C (3)
B18: Anatomía Humana I | C18: PTC3-LM | D18: LM | E18: 6 | F18: 35
B19: Histología I | C19: E.E. Edgar García Casas | D19: LM | E19: 5 | F19: 35
B20: Bioquímica | C20: Dr. Juan Carlos Barragán Gálvez | D20: LCB | E20: 6 | F20: 35
B21: Embriología | C21: PTC10-LM | D21: LM | E21: 5 | F21: 35
B22: Historia del Pensamiento Filosófico | C22: Dr. Guadalupe Gabriel Durán Férman | D22: DEP | E22: 4 | F22: 35
B24: 114-D (4)
B25: Anatomía Humana I | C25: PTC13-LM | D25: LM | E25: 6 | F25: 35
B26: Histología I | C26: E.E. Edgar García Casas | D26: LM | E26: 5 | F26: 35
B27: Bioquímica | C27: M.B.E. Ruth Monserrat Rodríguez Hernández | D27: LCB | E27: 6 | F27: 35
B28: Embriología | C28: PTC10-LM | D28: LM | E28: 5 | F28: 35
B29: Historia del Pensamiento Filosófico | C29: M.A.P. Diego Toto Jiménez | D29: LAP | E29: 4 | F29: 35
B31: 314-A
B32: Fisiología I | C32: PTC11-LM | D32: LM | E32: 6 | F32: 42
B33: Bacteriología y Micología Médica | C33: M.C.C.A.R.B. Guilibaldo Gabriel Zurita Vásquez | D33: LCB | E33: 6 | F33: 42
B34: Inmunología | C34: E.P.C. Yuniza Jocabeth Hernández Morales | D34: LM | E34: 5 | F34: 42
B35: Psicología Médica | E35: 4 | F35: 42
B36: Historia y Antropología Médica | C36: Méd. Guadalupe Ithalivi Olivera Domínguez | D36: LM | E36: 4 | F36: 42
B38: 314-B
B39: Fisiología I | C39: PTC11-LM | D39: LM | E39: 6 | F39: 42
B40: Bacteriología y Micología Médica | C40: M.C.C.A.R.B. Guilibaldo Gabriel Zurita Vásquez | D40: LCB | E40: 6 | F40: 42
B41: Inmunología | C41: E.P.C. Yuniza Jocabeth Hernández Morales | D41: LM | E41: 5 | F41: 42
B42: Psicología Médica | E42: 4 | F42: 42
B43: Historia y Antropología Médica | C43: M.S.P. Pablo Cataneo Pérez | D43: LM | E43: 4 | F43: 42
B45: 314-C
B46: Fisiología I | C46: PTC11-LM | D46: LM | E46: 6 | F46: 42
...

Sheet LO
A1: ASIGNACIÓN DE MATERIAS PARA EL SEMESTRE 26-27A
B2: Materia | C2: Profesor asignado | D2: PE-Adscripción | E2: Horas por semana | F2: Número de alumnos
B3: 113-A
B4: Anatomía y Fisiología Humana | C4: E.M.F. Arturo José Moreno Juárez | D4: LM | E4: 6
B5: Embriología Aplicada a la Odontología | C5: PTC8-LM | D5: LM | E5: 5
B6: Bioquímica Aplicada a la Odontología | C6: M.B.E. Diego Sait Cruz Hernández | D6: LCB | E6: 5
B7: Historia del Pensamiento Filosófico | C7: M.F. Araceli Luz Alva Rodríguez Martínez | D7: LCE | E7: 5
B8: Materiales Dentales | C8: C.D. Luis Bernardo Martínez Martínez | D8: LO | E8: 6 | G8: Materia que requiere de prácticas en laboratorio
B10: 113-B
B11: Anatomía y Fisiología Humana | C11: E.M.F. Arturo José Moreno Juárez | D11: LM | E11: 6
B12: Embriología Aplicada a la Odontología | C12: PTC8-LM | D12: LM | E12: 5
B13: Bioquímica Aplicada a la Odontología | C13: M.C. Andrea Itayetzzi Ortiz García | D13: LCB | E13: 5
B14: Historia del Pensamiento Filosófico | C14: Dra. Deisy Coromoto Rebolledo López | D14: DEP | E14: 5
B15: Materiales Dentales | C15: L.O. Yamile Yolotzin Vásquez Ríos | D15: LO | E15: 6 | G15: Materia que requiere de prácticas en laboratorio
B17: 113-C
B18: Anatomía y Fisiología Humana | C18: E.M.F. Arturo José Moreno Juárez | D18: LM | E18: 6
B19: Embriología Aplicada a la Odontología | C19: PTC8-LM | D19: LM | E19: 5
B20: Bioquímica Aplicada a la Odontología | C20: M.C. Andrea Itayetzzi Ortiz García | D20: LCB | E20: 5
B21: Historia del Pensamiento Filosófico | C21: Dr. Horacio González Pérez | D21: DEP | E21: 5
B22: Materiales Dentales | C22: L.O. Yamile Yolotzin Vásquez Ríos | D22: LO | E22: 6 | G22: Materia que requiere de prácticas en laboratorio
B24: 113-D
B25: Anatomía y Fisiología Humana | C25: E.M.F. Arturo José Moreno Juárez | D25: LM | E25: 6
B26: Embriología Aplicada a la Odontología | C26: PTC7-LM | D26: LM | E26: 5
B27: Bioquímica Aplicada a la Odontología | C27: M.C. Andrea Itayetzzi Ortiz García | D27: LCB | E27: 5
B28: Historia del Pensamiento Filosófico | C28: Dr. Horacio González Pérez | D28: DEP | E28: 5
B29: Materiales Dentales | C29: C.D. Luis Bernardo Martínez Martínez | D29: LO | E29: 6 | G29: Materia que requiere de prácticas en laboratorio
B31: 113-E
B32: Anatomía y Fisiología Humana | C32: Méd. Jennifer de la Luz Santos Santos | D32: LM | E32: 6
B33: Embriología Aplicada a la Odontología | C33: PTC7-LM | D33: LM | E33: 5
B34: Bioquímica Aplicada a la Odontología | C34: Dra. Melisa Karina Chacón Lázaro | D34: LCB | E34: 5
B35: Historia del Pensamiento Filosófico | C35: Dr. Joselito Fernández Tapia | D35: DEP | E35: 5
B36: Materiales Dentales | C36: L.O. César Yazid Martínez Martínez | D36: LO | E36: 6 | G36: Materia que requiere de prácticas en laboratorio
B38: 113-F
B39: Anatomía y Fisiología Humana | C39: Méd. Jennifer de la Luz Santos Santos | D39: LM | E39: 6
B40: Embriología Aplicada a la Odontología | C40: PTC7-LM | D40: LM | E40: 5
B41: Bioquímica Aplicada a la Odontología | C41: Dr. Abisaí Martínez Sánchez | D41: LCB | E41: 5
B42: Historia del Pensamiento Filosófico | C42: Dr. Mauricio Sosa Montes | D42: LAP | E42: 5
B43: Materiales Dentales | C43: L.O. Joel Abisai Hernández López | D43: LO | E43: 6 | G43: Materia que requiere de prácticas en laboratorio
B45: 113-G
B46: Anatomía y Fisiología Humana | C46: Méd. Jennifer de la Luz Santos Santos | D46: LM | E46: 6 | F46: PTC7-LM
...

Sheet LE
A1: ASIGNACIÓN DE MATERIAS PARA EL SEMESTRE 26-27A
B2: Materia | C2: Profesor asignado | D2: PE-Adscripción | E2: Horas por semana | F2: Número de alumnos
B3: 103-A PE 2024
B4: Bases Epistemológicas de la Enfermería | C4: M.E.A.T.E. Daniela Alonso Osorio | D4: LE | E4: 5
B5: Bioquímica para Enfermería | C5: M.C.I.B. Ericay Berenice Martínez Ramos | D5: LCB | E5: 6
B6: Historia del Pensamiento Filosófico | C6: Dra. Roxana Nayeli Guerrero Sotelo | D6: LE | E6: 4
B7: Anatomía Humana | C7: L.E. Amalia Hernández Blas | D7: LE | E7: 5
B8: Sociología y Salud | C8: M.C.E. Douglas Crittenden Nance | D8: LE | E8: 4
B10: 103-B PE 2024
B11: Bases Epistemológicas de la Enfermería | C11: L.E. Yarely Yaneth Zurita López | D11: LE | E11: 5
B12: Bioquímica para Enfermería | C12: M.C.I.B. Ericay Berenice Martínez Ramos | D12: LCB | E12: 6
B13: Historia del Pensamiento Filosófico | C13: Dra. Maria Guadalupe Temores Alcántara | D13: DEP | E13: 4
B14: Anatomía Humana | C14: L.E. Amalia Hernández Blas | D14: LE | E14: 5
B15: Sociología y Salud | C15: M.C.E. Douglas Crittenden Nance | D15: LE | E15: 4
B17: 103-C PE 2024
B18: Bases Epistemológicas de la Enfermería | C18: L.E. Yarely Yaneth Zurita López | D18: LE | E18: 5
B19: Bioquímica para Enfermería | C19: M.C.I.B. Ericay Berenice Martínez Ramos | D19: LCB | E19: 6
B20: Historia del Pensamiento Filosófico | C20: Dra. Maria Guadalupe Temores Alcántara | D20: DEP | E20: 4
B21: Anatomía Humana | C21: PTC-LE1 | D21: LE | E21: 5
B22: Sociología y Salud | C22: PTC-LE2 | D22: LE | E22: 4
B24: 103-D PE 2024
B25: Bases Epistemológicas de la Enfermería | C25: M.S.P. Maleni Rodríguez García | D25: LE | E25: 5
B26: Bioquímica para Enfermería | C26: Dr. Abisaí Martínez Sánchez | D26: LCB | E26: 6
B27: Historia del Pensamiento Filosófico | C27: M.T.C.A. Rolando Pedro Gabriel | D27: LCE | E27: 4 | F27: Lo cubrirá informatica
B28: Anatomía Humana | C28: PTC-LE1 | D28: LE | E28: 5
B29: Sociología y Salud | E29: 4
B31: 103-E PE 2024
B32: Bases Epistemológicas de la Enfermería | C32: M.E.S. Adriana Zúñiga Jiménez | D32: LE | E32: 5
B33: Bioquímica para Enfermería | C33: Dr. Abisaí Martínez Sánchez | D33: LCB | E33: 6
B34: Historia del Pensamiento Filosófico | C34: M.I.T.I. Oswaldo Rey Ávila Barrón | D34: LCE | E34: 4 | F34: Lo cubrirá informatica
B35: Anatomía Humana | C35: M.A.I.S. Amelia Roselia Juárez Agudo | D35: LE | E35: 5
B36: Sociología y Salud | C36: Dr. Gerardo Roberto Aragón Gonzalez | D36: LE | E36: 4
B38: 103-F PE 2024
B39: Bases Epistemológicas de la Enfermería | C39: M.E.S. Adriana Zúñiga Jiménez | D39: LE | E39: 5
B40: Bioquímica para Enfermería | C40: Dra. Karla Esmeralda Tello Ortega | D40: LCB | E40: 6
B41: Historia del Pensamiento Filosófico | C41: Dra. Reyna Minerva Hernández Vásquez | D41: LCE | E41: 4
B42: Anatomía Humana | C42: M.A.I.S. Amelia Roselia Juárez Agudo | D42: LE | E42: 5
B43: Sociología y Salud | C43: Dr. Gerardo Roberto Aragón Gonzalez | D43: LE | E43: 4
B45: 103-G PE 2024
B46: Bases Epistemológicas de la Enfermería | C46: M.E.A.T.E. Daniela Alonso Osorio | D46: LE | E46: 5
...

Sheet LN
A1: ASIGNACIÓN DE MATERIAS PARA EL SEMESTRE 26-27A
B2: Materia | C2: Profesor asignado | D2: PE-Adscripción | E2: Horas por semana | F2: Número de alumnos
B3: 107-A PE 2025
B4: Fundamentos de Nutrición Humana | C4: M.S.P. Felipe de Jesús Parada Luna | D4: LN | E4: 6 | F4: 25 | H4: M.C.A. Laura Jocelyn Valdez Gutiérrez
B5: Anatomía y fisiología Humana I | C5: PTC9-LM | D5: LM | E5: 6 | F5: 25
B6: Antropología de la Alimentación | C6: L.N. César Juárez Durán | D6: LN | E6: 5 | F6: 25
B7: Química Nutricional | C7: M.C.T.A. Iliana Vásquez Lara | D7: LCB | E7: 6 | F7: 25
B8: Historia del Pensamiento Filosófico | C8: Mtro. Diego Toto Jiménez | D8: LAP/LAM | E8: 4 | F8: 25
B10: 107-B PE 2025
B11: Fundamentos de Nutrición Humana | C11: M.S.P. Felipe de Jesús Parada Luna | D11: LN | E11: 6 | F11: 25 | H11: M.C.A. Laura Jocelyn Valdez Gutiérrez
B12: Anatomía y fisiología Humana I | C12: PTC9-LM | D12: LM | E12: 6 | F12: 25
B13: Antropología de la Alimentación | C13: L.N. César Juárez Durán | D13: LN | E13: 5 | F13: 25
B14: Química Nutricional | C14: M.C.T.A. Iliana Vásquez Lara | D14: LCB | E14: 6 | F14: 25
B15: Historia del Pensamiento Filosófico | C15: M.C.D.R.T. Lizeth Daniza Gómez Hernández | D15: LAP/LAM | E15: 4 | F15: 25
B17: 307 PE 2025
B18: Evaluación del Estado de Nutrición I | C18: M.S.P. Teófila Enriquez Almaraz | D18: LN | E18: 5 | F18: 34
B19: Educación Alimentaria Nutricional | C19: L.N. César Juárez Durán | D19: LN | E19: 5 | F19: 34
B20: Patología General y Trastornos Asociados a la Nutrición | D20: LM | E20: 5 | F20: 34
B21: Bioquímica Nutricional II | C21: Dra. Claudia Villanueva Cañongo | D21: LN | E21: 5 | F21: 34
B22: Microbiología de los Alimentos | C22: M.C.T.A. Iliana Vásquez Lara | D22: LCB | E22: 5 | F22: 34
B24: 507 PE 2017
B25: Cálculo y Laboratorio de Nutrición en el Ciclo de Vida | C25: M.S.P. Teófila Enriquez Almaraz | D25: LN | E25: 6 | F25: 43
B26: Gastroenterología Nutricional | D26: LM | E26: 5 | F26: 43
B27: Laboratorio de Evaluación del Estado de Nutrición | C27: Dra. Maria Dolores Caballero Sánchez | D27: LN | E27: 5 | F27: 43
B28: Administración general | C28: Dra. Reyna Minerva Hernández Vásquez | D28: LCE | E28: 5 | F28: 43
B29: Nutrición Poblacional II | C29: M.S.P. Eric Ramirez Bohorquez | D29: LN | E29: 4 | F29: 43
B31: 707 PE 2017
B32: Cálculo y Dietoterapia en Situaciones Patológicas II | C32: Dra. Maria Dolores Caballero Sánchez | D32: LN | E32: 6 | F32: 36
B33: Nutrición y Farmacología | D33: LM | E33: 4 | F33: 36
B34: Química de los Alimentos | C34: M.C.T.A. Iliana Vásquez Lara | D34: LCB | E34: 4 | F34: 36 | H34: M.C.A. Laura Jocelyn Valdez Gutiérrez
B35: Análisis de Alimentos | C35: Dra. Claudia Villanueva Cañongo | D35: LN | E35: 6 | F35: 36
B36: Administración de Servicios de Alimentos II | C36: M.S.P. Felipe de Jesús Parada Luna | D36: LN | E36: 5 | F36: 36
B38: 907 PE 2017
B39: Atención Clínica Nutricional | C39: M.N.C. Griselda Belén Avendaño Rodríguez | D39: LN | E39: 6 | F39: 34
B40: Bioestadística | C40: M.C.M. Jesús Pacheco Mendoza | D40: LI | E40: 5 | F40: 34
B41: Nutrición en Salud Pública | C41: M.S.P. Eric Ramirez Bohorquez | D41: LN | E41: 4 | F41: 34
B42: Métodos y Técnicas de Investigación | E42: 5 | F42: 34
B43: Tecnología de Alimentos de Origen Animal | C43: Dra. Claudia Villanueva Cañongo | D43: LN | E43: 5 | F43: 34
H48: *M.C.A. Laura Jocelyn Valdez Gutiérrez 1 grupo de enfermería/Odonto
C57: PROFESORES DE LN | D57: TOTAL DE MATERIAS | E57: Otras carreras | F57: Total | G57: Total alumnos | H57: Total horas a la semana | I57: Status | J57: Reincorporación | K57: Horario Laboral
...

Sheet LCE
A1: ASIGNACIÓN DE MATERIAS PARA EL SEMESTRE 26-27A
B2: Materia | C2: Profesor asignado | D2: PE-Adscripción | E2: Horas por semana | F2: Número de alumnos
B3: 104
B4: Introducción a las Ciencias Administrativas | C4: M.E.O. Mariano Olvera Ramírez | D4: LCE | E4: 5 | F4: 28 | G4: CEDGE - DO
B5: Informática empresarial | C5: M.T.E. Everardo de Jesús Pacheco Antonio | D5: LI | E5: 5 | F5: 28 | G5: CEDGE, Sala de Cómputo
B6: Matemáticas para ciencias empresariales | C6: M.E. Jorge Lamas Carlos | D6: LCE | E6: 5 | F6: 28 | G6: Aula con mesas, sillas y cañon
B7: Introducción a la contabilidad | C7: L.C. Zayra Trujillo Báez | D7: LCE | E7: 5 | F7: 28 | G7: Aula con mesas, sillas y cañon | H7: Asignar 2 clases de 2 horas y una clase de 1 hora.
B8: Historia del Pensamiento Filosófico | C8: Dra. Maria Guadalupe Temores Alcántara | D8: LCE | E8: 4 | F8: 28
B10: 304
B11: Administración de Recursos Humanos II | C11: Dra. Reyna Minerva Hernández Vásquez | D11: LCE | E11: 5 | F11: 25
B12: Administración de Compras e Inventarios | C12: M.C.P.E.D.R. Elsa A. Mendoza Cortés | D12: LCE | E12: 5 | F12: 25
B13: Estadística Inferencial | C13: Dr. Horacio González Pérez | D13: DEP | E13: 5 | F13: 25
B14: Contabilidad de Costos | C14: M.I.A. Hadya Concepción Díaz Ortíz | D14: LCE | E14: 5 | F14: 25 | G14: No asignar clase a las 16:00
B15: Derecho Mercantil | C15: M.G.P. Rafael Rentería Gaeta | D15: LAP | E15: 5 | F15: 25 | G15: Clase de 8:00 a 9:00
B17: 504
B18: Administración de Sueldos y Salarios | C18: L.C. Zayra Trujillo Báez | D18: LCE | E18: 5 | F18: 15 | G18: Aula con mesas, sillas y cañon | H18: Asignar 2 clases de 2 horas y una clase de 1 hora.
B19: Taller de Metodología de la Investigación | C19: M.E.O. Mariano Olvera Ramírez | D19: LCE | E19: 5 | F19: 15 | G19: CEDGE - DO
B20: Macroeconomía | C20: Dr. Ramón Inzunza Acosta | D20: LCE | E20: 5 | F20: 15 | G20: CEDGE - Sala Computo
B21: Finanzas Empresariales I | C21: M.F. Máximo Jorge Saavedra García | D21: LCE | E21: 5 | F21: 15
B22: Derecho Fiscal | C22: M.E. Benito Güizado Hernández | D22: LAP | E22: 5 | F22: 15
B24: 704
B25: Administración Estratégica de Ventas | C25: M.C.D.R.T. Víctor Santiago Sarmiento | D25: LCE | E25: 5 | F25: 21 | G25: CEDGE - Sala SIG
B26: Investigación de Operaciones | C26: M.E. Jorge Lamas Carlos | D26: LGDM | E26: 5 | F26: 21 | G26: Aula con mesas, sillas y cañon
B27: Economía del Sector Público México | C27: Dr. Ramón Inzunza Acosta | D27: LCE | E27: 5 | F27: 21
B28: Sistema Financiero | C28: M.F. Máximo Jorge Saavedra García | D28: LCE | E28: 5 | F28: 21
B29: Planeación Estratégica | C29: M.I.S. Fabiola Crespo Barrios | D29: LCE | E29: 5 | F29: 21
B31: 904
B32: Cultura Empresarial | C32: M.E.O. Mariano Olvera Ramírez | D32: LCE | E32: 5 | F32: 19 | G32: CEDGE - DO
B33: Emprendimiento de Negocios | C33: M.C.D.R.T. Víctor Santiago Sarmiento | D33: LCE | E33: 5 | F33: 19 | G33: CEDGE - DO
B34: Comercio Exterior | C34: Dr. Ramón Inzunza Acosta | D34: LCE | E34: 5 | F34: 19 | G34: CEDGE - Sala SIG
B35: Finanzas Corporativas | C35: M.I.S. Fabiola Crespo Barrios | D35: LCE | E35: 5 | F35: 19
B36: Gestión de la Calidad | C36: M.I.A. Hadya Concepción Díaz Ortíz | D36: LCE | E36: 5 | F36: 19 | G36: CEDGE - Sala Computo
C47: PROFESORES DE LCE | D47: TOTAL DE MATERIAS | E47: Otras carreras | F47: Total | G47: Total alumnos | H47: Total horas a la semana | I47: Status | J47: Reincorporación | K47: Horario Laboral | L47: Observaciones
B48: 1 | C48: Dr. Pedro Durán Férman | D48: =COUNTIF($C$4:$C$43,C48) -> 0 | E48: ='Asignación-Profesor'!D129-D48 -> 1 | F48: =E48+D48 -> 1 | G48: ='Asignación-Profesor'!P129 -> 0 | H48: ='Asignación-Profesor'!Q129 -> 5 | K48: 09:00 - 14:00 y 16:00 - 19:00
B49: 2 | C49: Dr. Ramón Inzunza Acosta | D49: =COUNTIF($C$4:$C$43,C49) -> 3 | E49: ='Asignación-Profesor'!D130-D49 -> 0 | F49: =E49+D49 -> 3 | G49: ='Asignación-Profesor'!P130 -> 55 | H49: ='Asignación-Profesor'!Q130 -> 15 | K49: 09:00 - 14:00 y 16:00 - 19:00
B50: 3 | C50: M.I.S. Fabiola Crespo Barrios | D50: =COUNTIF($C$4:$C$43,C50) -> 2 | E50: ='Asignación-Profesor'!D131-D50 -> 1 | F50: =E50+D50 -> 3 | G50: ='Asignación-Profesor'!P131 -> 67 | H50: ='Asignación-Profesor'!Q131 -> 15 | K50: 09:00 - 14:00 y 16:00 - 19:00
B51: 4 | C51: M.E.O. Mariano Olvera Ramírez | D51: =COUNTIF($C$4:$C$43,C51) -> 3 | E51: ='Asignación-Profesor'!D132-D51 -> 0 | F51: =E51+D51 -> 3 | G51: ='Asignación-Profesor'!P132 -> 62 | H51: ='Asignación-Profesor'!Q132 -> 15 | K51: 8:00-13:00 y 16:00-19:00
B52: 5 | C52: M.I.A. Hadya Concepción Díaz Ortíz | D52: =COUNTIF($C$4:$C$43,C52) -> 2 | E52: ='Asignación-Profesor'!D133-D52 -> 1 | F52: =E52+D52 -> 3 | G52: ='Asignación-Profesor'!P133 -> 68 | H52: ='Asignación-Profesor'!Q133 -> 15 | K52: 8:00-13:00 y 16:00-19:00 | L52: Asignar clase de 8:00 a 13:00
B53: =B52+1 -> 6 | C53: Dra. Reyna Minerva Hernández Vásquez | D53: =COUNTIF($C$4:$C$43,C53) -> 1 | E53: ='Asignación-Profesor'!D134-D53 -> 3 | F53: =E53+D53 -> 4 | G53: ='Asignación-Profesor'!P134 -> 68 | H53: ='Asignación-Profesor'!Q134 -> 18 | K53: 09:00 - 14:00 y 16:00 - 19:00 | L53: Asignar clases de 12 a 14:00 y de 16:00 a 18:00. En planta baja
B54: =B53+1 -> 7 | C54: L.C. Zayra Trujillo Báez | D54: =COUNTIF($C$4:$C$43,C54) -> 2 | E54: ='Asignación-Profesor'!D135-D54 -> 1 | F54: =E54+D54 -> 3 | G54: ='Asignación-Profesor'!P135 -> 57 | H54: ='Asignación-Profesor'!Q135 -> 15 | K54: 8:00-13:00 y 16:00-19:00
...

Sheet LI
A1: ASIGNACIÓN DE MATERIAS PARA EL SEMESTRE 26-27A
B2: Materia | C2: Profesor asignado | D2: PE-Adscripción | E2: Horas por semana | F2: Número de alumnos
B3: 106-A PE 2022
B4: Diseño Estructurado de Algoritmos | C4: M.T.E. Everardo de Jesús Pacheco Antonio | D4: LI | E4: 5 | F4: 14
B5: Administración | C5: M.I.S. Fabiola Crespo Barrios | D5: LCE | E5: 5 | F5: 27
B6: Historia del Pensamiento Filosófico | C6: Dr. Guadalupe Gabriel Durán Férman | D6: DEP | E6: 5 | F6: 27
B7: Lógica Matemática | C7: M.C.M. Jesús Pacheco Mendoza | D7: LI | E7: 5 | F7: 14 | G7: El Mtro Pacheco está en la disponibilidad de atender el grupo fusionado al ser de 27 alumnos
B8: Cálculo I | C8: M.C. Enrique García Reyes | D8: LI | E8: 5 | F8: 27 | G8: El Mtro Enrique está en la disponibilidad de atender el grupo fusionado al ser de 27 alumnos
B10: 106-B PE 2022
B11: Diseño Estructurado de Algoritmos | C11: M.C.C Eliezer Álcazar Silva | D11: LI | E11: 5 | F11: 13 | G11: Esta materia es difícil y podría divirse solo para esta materia el grupo
B12: Administración | C12: M.I.S. Fabiola Crespo Barrios * | D12: LCE | E12: 5 | G12: Se une con 106-A
B13: Historia del Pensamiento Filosófico | C13: Dr. Guadalupe Gabriel Durán Férman * | D13: DEP | E13: 5 | G13: Se une con 106-A
B14: Lógica Matemática | C14: M.C.M. Jesús Pacheco Mendoza* | D14: LI | E14: 5 | F14: 13 | G14: Se une con 106-A
B15: Cálculo I | C15: M.C. Enrique García Reyes * | D15: LI | E15: 5 | G15: Se une con 106-A
B17: 306 A PE 2022
B18: Estructuras de Datos | C18: M.C.C. Lirio Ruíz Guerra | D18: LI | E18: 5 | F18: 24
B19: Electrónica Digital | C19: Dr. Amando Alejandro Ruiz Figueroa | D19: LI | E19: 6 | F19: 24
B20: Contabilidad y Finanzas | C20: M.I.A. Hadya Concepción Díaz Ortíz | D20: LCE | E20: 5 | F20: 24 | G20: Asignar Sala de Redes en CETI
B21: Teoría de Autómatas | C21: M.C. Mónica Pérez Meza | D21: LI | E21: 5 | F21: 24 | H21: Podrían haber bajas
B22: Álgebra Lineal | C22: M.C. Enrique García Reyes | D22: LI | E22: 5 | F22: 24
B24: 306 B PE 2022
B25: Estructuras de Datos | E25: 5 | F25: 28
B26: Electrónica Digital | E26: 6 | F26: 28
B27: Contabilidad y Finanzas | E27: 5 | F27: 28
B28: Teoría de Autómatas | E28: 5 | F28: 28
B29: Álgebra Lineal | E29: 5 | F29: 28
B31: 506 PE 2022
B32: Paradigmas de Programación II | C32: M.T.E. Everardo de Jesús Pacheco Antonio | D32: LI | E32: 5 | F32: 21
B33: Redes I | C33: Dr. Arisaí Darío Barragán López | D33: LI | E33: 5 | F33: 21
B34: Bases de Datos II | C34: M.C.C. Lirio Ruíz Guerra | D34: LI | E34: 5 | F34: 21 | H34: Podrían haber bajas
B35: Fundamentos de Sistemas Operativos | C35: M.I.T.I. Oswaldo Rey Ávila Barrón | D35: LI | E35: 5 | F35: 21
B36: Diseño Web | C36: M.C.C Eliezer Álcazar Silva | D36: LI | E36: 5 | F36: 21
B38: 706 PE 2022
B39: Tecnologías Web II | C39: M.T.I.E. Irving Ulises Hernández Miguel | D39: LI | E39: 5 | F39: 16
B40: Derecho y Legislación en Informática | C40: M.T.C.A. Rolando Pedro Gabriel | D40: LI | E40: 5 | F40: 16
B41: Bases de Datos Avanzadas | C41: M.C.C. Lirio Ruíz Guerra | D41: LI | E41: 5 | F41: 16
B42: Ingeniería de Software II | C42: Dr. Jesús Cruz Ahuactzi | D42: LI | E42: 5 | F42: 16
B43: Probabilidad y Estadística | C43: M.C. Enrique García Reyes | D43: LI | E43: 5 | F43: 16
B45: 906 PE 2022
B46: Metodología de la Investigación | C46: Dra. María Alejandra Sánchez Bandala | D46: DEP | E46: 5 | F46: 19
...

Sheet LAP
B2: Materia | C2: Profesor asignado | D2: PE-Adscripción | E2: Horas por semana | F2: Número de alumnos | I2: Aula solicitada | J2: Horario preferente | K2: Observaciones
B3: 105 PE 2024
B4: Introducción al Sistema Jurídico Mexicano | C4: M.E. Benito Güizado Hernández | D4: LAP | E4: 5 | F4: 13 | I4: Sala de Cabildos (CEDGE) | J4: 8:00-9:00 | K4: El Mtro. Benito ya tiene asignadas 4 clases
B5: Fundamentos de la Administración Pública | C5: Dr. Christian Arturo Cruz Meléndez | D5: LAP | E5: 5 | F5: 13 | I5: Sala SIG (CEDGE) | J5: 10:00-11:00
B6: Historia del Pensamiento Filosófico | C6: M.A.P. Diego Toto Jiménez | D6: LAP | E6: 5 | F6: 13 | I6: Aula | J6: 17:00-18:00 | K6: El Mtro. Diego Toto ha impartido HPF
B7: Historia Mundial | C7: Dra. Rocío Bravo Salazar | D7: LAP | E7: 5 | F7: 13 | I7: Sala de Desarrollo Organizacional (CEDGE) | J7: 12:00-13:00
B8: Matemáticas Aplicadas a las Ciencias Sociales | C8: M.E. Jorge Lamas Carlos | D8: LGDM | E8: 5 | F8: 13 | I8: Aula | J8: 9:00-10:00
B10: 305 PE 2024
B11: Derecho Administrativo | C11: M.E. Benito Güizado Hernández | D11: LAP | E11: 5 | F11: 15 | I11: Aula | J11: 10:00-11:00
B12: Microeconomía | C12: Dr. Mauricio Sosa Montes | D12: LAP | E12: 5 | F12: 15 | I12: Aula | J12: 08:00-9:00
B13: Enfoques y Tendencias de la Administración Pública | C13: Dr. Daniel Robles Torres | D13: DEP | E13: 5 | F13: 15 | I13: Aula DEP | J13: 9:00-10:00
B14: Ciencia Política | C14: M.C.P. Rocío Bravo Salazar | D14: LAP | E14: 5 | F14: 15 | I14: Sala de Cabildos (CEDGE) | J14: 11:00-12:00
B15: Gobierno y Asuntos Públicos | C15: M.P.P. Juan Carlos Mata Espinoza | D15: LAP | E15: 5 | F15: 15 | I15: Aula | J15: 17:00-18:00 | K15: El Mtro. Juan Carlos NO ha impartido HPF pero puede apoyar en asignaturas relacionadas con políticas públicas.
B17: 505 PE 2024
B18: Procesos de Gobierno en el Ámbito Municipal | C18: M.C.S. Rosario Maya Lucas | D18: LAP | E18: 5 | F18: 7 | I18: Aula | J18: 12:00-1:00 | K18: 0.70833333 | L18: La Mtra. Daniza ha impartido HPF
B19: Contabilidad Gubernamental | C19: M.C.D.R.T. Lizeth Daniza Gómez Hernández | D19: LAP | E19: 5 | F19: 7 | I19: Sala de Desarrollo Organizacional (CEDGE) | J19: 09:00-10:00
B20: Finanzas Públicas I | C20: M.F. Máximo Jorge Saavedra García | D20: LCE | E20: 5 | F20: 7 | I20: Sala de Cabildos (CEDGE) | J20: 17:00-18:00 | K20: 0.5 | L20: Unir con el grupo 905
B21: Sistemas de Información Geográfica | C21: Dra. Deisy Coromoto Rebolledo López | D21: DEP | E21: 5 | F21: 7 | I21: Sala SIG (CEDGE) | J21: 11:00-12:00 | K21: 0.41666667
B22: Implementación de Políticas Públicas | C22: M.P.P. Juan Carlos Mata Espinoza | D22: LAP | E22: 5 | F22: 7 | I22: Aula | J22: 10:00-11:00 | K22: 0.45833333
B24: 705 PE 2012
B25: Gestión de Recursos Humanos | C25: Dr. Christian Arturo Cruz Meléndez | D25: DEP | E25: 5 | F25: 15 | I25: Aula DEP | J25: 10:00-11:00
B26: Políticas Públicas II | C26: M.P.P. Juan Carlos Mata Espinoza | D26: LAP | E26: 5 | F26: 15 | I26: Sala SIG (CEDGE) | J26: 12:00- 1:00 | K26: 0.375
B27: Sistemas de Auditoría Gubernamental | C27: M.C.D.R.T. Lizeth Daniza Gómez Hernández | D27: LAP | E27: 5 | F27: 15 | I27: Aula | J27: 17:00-18:00
B28: Procesos de Gobierno en México (Ámbito Federal) | C28: M.E. Benito Güizado Hernández | D28: LAP | E28: 5 | F28: 15 | I28: Sala de Cabildos (CEDGE) | J28: 9:00-10:00 | K28: 0.5
B29: Gerencia Social | C29: Dra. Alicia Martínez Cruz | D29: LAP | E29: 4 | F29: 15 | I29: Aula | J29: 11:00 -12:00
B31: 905 PE 2012
B32: Ética y Rendición de Cuentas Públicas | C32: M.P.P. Juan Carlos Mata Espinoza | D32: DEP | E32: 4 | F32: 15 | I32: Aula DEP | J32: 10:00-11:00 | K32: Se programaron todas las materias por la mañana para que los alumnos puedan avanzar con su servicio social para evitar que en décimo semestre se saturen con las materias y las tesis.
B33: Planeación Estratégica | C33: M.A.E. Enrique Martínez Sánchez | D33: LAP | E33: 4 | F33: 15 | I33: Sala Cabildo (CEDGE) | J33: 12:00 - 1:00 | K33: 0.375
B34: Gestión y Administración Urbana | C34: Dr. Omar Ávila Flores | D34: LGDM | E34: 4 | F34: 15 | I34: Sala SIG (CEDGE) | J34: 8:00-9:00 | K34: Los alumnos podrían tomar inglés de 4:00 a 5:00 y biblioteca de 1:00 a 2:00
B35: Procesos de Gobierno en México (Ámbito Municipal) | C35: Dr. Arturo César López García | D35: LGDM | E35: 4 | F35: 15 | I35: Sala Cabildo (CEDGE) | J35: 11:00 - 12:00 | K35: Sala de Cabildos, asignar clase por la mañana
B36: Seminario de Tesis I | C36: Dr. Mauricio Sosa Montes | D36: LAP | E36: 5 | F36: 15 | I36: Aula | J36: 09:00-10:00
C49: PROFESORES DE LAP | D49: TOTAL DE MATERIAS | E49: Otras carreras | F49: Total | G49: Total alumnos | H49: Total horas a la semana | I49: Total alumnos | J49: Total horas a la semana | K49: Status | L49: Reincorporación | M49: Horario Laboral | N49: Observaciones
B50: 1 | C50: M.G.P. Rafael Rentería Gaeta | D50: =COUNTIF($C$5:$C$45,C50) -> 0 | E50: ='Asignación-Profesor'!D169-D50 -> 1 | F50: =E50+D50 -> 1 | I50: ='Asignación-Profesor'!P169 -> 25 | J50: ='Asignación-Profesor'!Q169 -> 5 | M50: 08:00 - 13:00 y 16:00 - 19:00
B51: 2 | C51: M.A.E. Enrique Martínez Sánchez | D51: =COUNTIF($C$5:$C$45,C51) -> 1 | E51: ='Asignación-Profesor'!D170-D51 -> 0 | F51: =E51+D51 -> 1 | I51: ='Asignación-Profesor'!P170 -> 15 | J51: ='Asignación-Profesor'!Q170 -> 4 | K51: Coordinación UNSIS Evaluación SEAES | M51: 09:00 - 14:00 y 16:00 - 19:00
B52: 3 | C52: Dra. Alicia Martínez Cruz | D52: =COUNTIF($C$5:$C$45,C52) -> 1 | E52: 1 | F52: =E52+D52 -> 2 | I52: 28 | J52: 10 | K52: Comisión de Planes Micro-Regional y Municipales | M52: 09:00 - 14:00 y 16:00 - 19:00 | N52: Comisión de Planes
B53: 4 | C53: M.A.P. Diego Toto Jiménez | D53: 1 | E53: 3 | F53: =E53+D53 -> 4 | I53: ='Asignación-Profesor'!P172 -> 48 | J53: ='Asignación-Profesor'!Q172 -> 9 | M53: 09:00 - 14:00 y 16:00 - 19:00
B54: 5 | C54: M.C.D.R.T. Lizeth Daniza Gómez Hernández | D54: =COUNTIF($C$5:$C$45,C54) -> 1 | E54: ='Asignación-Profesor'!D173-D54 -> 3 | F54: =E54+D54 -> 4 | I54: 22 | J54: 10 | M54: 09:00 - 14:00 y 16:00 - 19:00
B55: 6 | C55: M.P.P. Juan Carlos Mata Espinoza | D55: =COUNTIF($C$5:$C$45,C55) -> 4 | E55: ='Asignación-Profesor'!D174-D55 -> 0 | F55: =E55+D55 -> 4 | I55: 37 | J55: 15 | M55: 09:00 - 14:00 y 16:00 - 19:00
C56: Dra. Nina Martínez Cruz | D56: =COUNTIF($C$5:$C$45,C56) -> 0 | E56: ='Asignación-Profesor'!D175-D56 -> 1 | F56: =E56+D56 -> 1 | I56: 15 | J56: ='Asignación-Profesor'!Q175 -> 4 | K56: Comisión de Planes Micro-Regional y Municipales | M56: 09:00 - 14:00 y 16:00 - 19:00 | N56: Comisión de Planes
B57: 8 | C57: Dr. Mauricio Sosa Montes | D57: =COUNTIF($C$5:$C$45,C57) -> 2 | E57: ='Asignación-Profesor'!D176-D57 -> 1 | F57: =E57+D57 -> 3 | I57: 30 | J57: 10 | M57: 09:00 - 14:00 y 16:00 - 19:00 | N57: Proyectos de investigación (protocolos) de los alumnos de del Grupo 905 y requiere tiempo para asesorías.
...

Sheet LGDM
A1: ASIGNACIÓN DE MATERIAS PARA EL SEMESTRE 26-27A
B2: Materia | C2: Profesor asignado | D2: PE-Adscripción | E2: Horas por semana | F2: Número de alumnos
B3: 117 | G3: Horarios/Ejemplo:
B4: Fundamentos de la Administración Pública | C4: M.C.P. Joann Etienne Olivier Picard | D4: LGDM | E4: 5 | F4: 14 | G4: 09:00-10:00 | H4: Sala SIG
B5: Historia y Cultura de los Pueblos Originarios | C5: Dr. Joaquín Huitzilihuitl Camacho Vera | D5: DEP | E5: 5 | F5: 14 | G5: 13:00-14:00 | H5: Aula con mesas, sillas y cañon en DEP
B6: Contabilidad I | C6: L.C. Zayra Trujillo Báez | D6: LCE | E6: 5 | F6: 14 | G6: 11:00-12:00 | H6: Aula con mesas, sillas y cañon
B7: Matemáticas Aplicadas a las Ciencias Sociales | C7: M.E. Jorge Lamas Carlos | D7: LGDM | E7: 5 | F7: 14 | G7: 08:00-09:00 | H7: Aula con mesas, sillas y cañon
B8: Historia del Pensamiento Filosófico | C8: M.D.G.P.L. Eleazar Brena García | D8: LGDM | E8: 5 | F8: 14 | G8: 12:00-13:00 | H8: por la mañana, sin preferencia de aulas
G10: 10:00-11:00 | H10: Asesoría
C21: PROFESORES DE LAP | D21: TOTAL DE MATERIAS | E21: Otras carreras | F21: Total | G21: Total alumnos | H21: Total horas a la semana | I21: Status | J21: Reincorporación | K21: Horario Laboral
B22: 1 | C22: M.C.P. Joann Etienne Olivier Picard | D22: =COUNTIF($C$4:$C$19,C22) -> 1 | E22: 0 | F22: =E22+D22 -> 1 | G22: ='Asignación-Profesor'!P184 -> 15 | H22: ='Asignación-Profesor'!Q184 -> 5 | K22: 09:00-14:00 / 16:00-19:00
B23: 2 | C23: M.P.E.M. Emanuel Lorenzo Ramírez Arellanes | D23: =COUNTIF($C$4:$C$19,C23) -> 0 | E23: ='Asignación-Profesor'!D185-D23 -> 2 | F23: =E23+D23 -> 2 | G23: ='Asignación-Profesor'!P185 -> 4 | H23: ='Asignación-Profesor'!Q185 -> 9 | I23: Comisión de Planes Micro-Regional y Municipales | K23: 09:00-14:00 / 16:00-19:00
B24: 3 | C24: M.C.S. Rosario Maya Lucas | D24: 0 | E24: 2 | F24: =E24+D24 -> 2 | G24: ='Asignación-Profesor'!P186 -> 7 | H24: 10 | I24: Comisión de Planes Micro-Regional y Municipales | K24: 09:00-14:00 / 16:00-19:00
B25: 4 | C25: M.D.G.P.L. Eleazar Brena García | D25: =COUNTIF($C$4:$C$19,C25) -> 1 | E25: ='Asignación-Profesor'!D187-D25 -> 2 | F25: =E25+D25 -> 3 | G25: ='Asignación-Profesor'!P187 -> 23 | H25: ='Asignación-Profesor'!Q187 -> 15 | I25: Comisión SEAES | K25: 09:00-14:00 / 16:00-19:00
B26: 5 | C26: M.E. Jorge Lamas Carlos | D26: =COUNTIF($C$4:$C$19,C26) -> 1 | E26: ='Asignación-Profesor'!D188-D26 -> 4 | F26: =E26+D26 -> 5 | G26: ='Asignación-Profesor'!P188 -> 80 | H26: ='Asignación-Profesor'!Q188 -> 25 | K26: 08:00-13:00 / 16:00-19:00 | L26: poner todas las clases en la mañana
B27: 6 | C27: Dr. Arturo César López García | D27: =COUNTIF($C$4:$C$19,C27) -> 0 | E27: ='Asignación-Profesor'!D189-D27 -> 2 | F27: =E27+D27 -> 2 | G27: ='Asignación-Profesor'!P189 -> 20 | H27: ='Asignación-Profesor'!Q189 -> 9 | I27: SNII - Nivel 1, Comisión de Planes Micro-Regional y Municipales | K27: 09:00-14:00 / 16:00-19:00
B28: 7 | C28: Dr. Omar Ávila Flores | D28: =COUNTIF($C$4:$C$19,C28) -> 0 | E28: ='Asignación-Profesor'!D190-D28 -> 3 | F28: =E28+D28 -> 3 | G28: ='Asignación-Profesor'!P190 -> 24 | H28: ='Asignación-Profesor'!Q190 -> 14 | I28: SNII - Nivel 1, Dirección de tesis de doctorado y licenciatura | K28: 08:00-13:00 / 16:00-19:00

Sheet LAM
A1: ASIGNACIÓN DE MATERIAS PARA EL SEMESTRE 26-27A
B2: Materia | C2: Profesor asignado | D2: PE-Adscripción | E2: Horas por semana | F2: Número de alumnos
B3: 701
B4: Auditoría Gubernamental | D4: LGDM | E4: 5 | F4: 4
B5: Sustentabilidad y Gestión Local | C5: M.D.G.P.L. Eleazar Brena García | D5: LGDM | E5: 5 | F5: 4 | G5: asignar clase por la mañana
B6: Metodología de la Investigación Cuantitativa | C6: M.E. Jorge Lamas Carlos | D6: LGDM | E6: 5 | F6: 4 | G6: asignar clase por la mañana
B7: Planeación, Programación y Presupuesto | C7: M.P.E.M. Emanuel Lorenzo Ramírez Arellanes | D7: LGDM | E7: 5 | F7: 4 | G7: Sala de Cabildos, asignar clase por la mañana
B8: Desarrollo Urbano | C8: Dr. Omar Ávila Flores | D8: LGDM | E8: 5 | F8: 4 | G8: Sala de Cabildos, asignar clase por la mañana
B10: 901
B11: Administración de Obras Públicas | C11: Dr. Omar Ávila Flores | D11: LGDM | E11: 5 | F11: 5 | G11: Sala de Cabildos, asignar clase por la mañana
B12: Administración de Servicios Públicos Municipales | C12: Dr. Oscar David Valencia López | D12: DEP | E12: 5 | F12: 5 | G12: en DEP
B13: Sistemas de Evaluación y Seguimiento | C13: Dr. Arturo César López García | D13: LGDM | E13: 5 | F13: 5 | G13: Sala de Cabildos, asignar clase por la mañana
B14: Formulación y Evaluación de Proyectos de Inversión | C14: M.D.G.P.L. Eleazar Brena García | D14: LGDM | E14: 5 | F14: 5 | G14: asignar clase por la mañana
B15: Taller de Redacción de Tesis I | C15: Dr. Jose Rudier López Hernández | D15: DEP | E15: 5 | F15: 5 | G15: asignar clase por la mañana, en DEP

Sheet DEP
A1: ASIGNACIÓN DE MATERIAS PARA EL SEMESTRE 26-27A
B2: Materia | C2: Profesor asignado | D2: PE-Adscripción | E2: Horas por semana | F2: Número de alumnos
B3: MPEM 108
B4: Fundamentos, Métodos y Técnicas de Planeación | C4: M.P.E.M. Emanuel Lorenzo Ramírez Arellanes | D4: LGDM | E4: 4 | F4: asignar clase por la mañana
B5: Teoría del Desarrollo | C5: Dr. Jose Rudier López Hernández | D5: DEP | E5: 4
B6: Teoría y Marco Jurídico del Municipio | C6: M.C.S. Rosario Maya Lucas | D6: LGDM | E6: 4
B7: Estadística para las Ciencias Sociales | C7: Dr. Horacio González Pérez | D7: DEP | E7: 4
B8: Taller de Tesis I: Protocolo de Investigación | C8: Dr. Guadalupe Gabriel Durán Férman | D8: DEP | E8: 4
B10: MPEM 308
B11: Diagnóstico Municipal para la Planeación | C11: Dra. Nina Martínez Cruz | D11: LAP | E11: 4
B12: Ordenamiento Territorial Sostenible | C12: Dra. Deisy Coromoto Rebolledo López | D12: DEP | E12: 4
B13: Análisis de Información de Campo | C13: Dr. Joaquín Huitzilihuitl Camacho Vera | D13: DEP | E13: 4
B14: OPT1 Gestión de proyectos de Innovación Social en el Municipio | C14: Dr. Daniel Robles Torres | E14: 4
B16: MSP 109 - PE2026
B17: Demografia y salud pública | C17: Dra. Maria Dolores Caballero Sánchez* | D17: LN | E17: 4
B18: Salud, Sociedad y Derechos Humanos | C18: Dra. Maria Guadalupe Temores Alcántara | D18: DEP | E18: 4
B19: Epidemiología I | C19: Dr. José Eduardo Orellana Centeno | D19: LO | E19: 4
B20: Bioestadística I | C20: Dr. Alejandro Jarillo Silva | D20: LI | E20: 4
B21: Metodología de la Investigación Científica | C21: Dra. Araceli Hernández Flores | D21: DEP | E21: 4
B22: Metodología de la Investigación Cualitativa | C22: Dra. María Alejandra Sánchez Bandala | D22: DEP | E22: 4
B24: MSP 309 - PE2016
B25: Políticas de Salud | C25: M.S.P. Teófila Enriquez Almaraz | D25: LN | E25: 4
B26: Seminario de Investigación | C26: Dr. Roberto Ariel Abeldaño Zúñiga | D26: DEP | E26: 4
B27: OPT-Farmacología Regional y Salud Pública | C27: Dr. Hady Keita | D27: DEP | E27: 4
B28: OPT-Enfermedades transmitidas por vector | C28: Dra. Lilian Arzeta Pino | E28: 4
B30: MGE 110 - PE2026
B31: Gobierno Electrónico y Administración Pública | C31: Dr. Christian Arturo Cruz Meléndez | D31: DEP | E31: 4
B32: Derecho Digital y Protección de Datos | C32: Dr. Gerardo Roberto Aragón Gonzalez | D32: LE | E32: 4
B33: Interoperabilidad y Privacidad en la Administración Digital | C33: Dra. Aidee Cruz Barragán | D33: LI | E33: 4
B34: Gobernanza Digital y Ética Pública | C34: Dr. Oscar David Valencia López | D34: DEP | E34: 4
B35: Investigación en Ciencias Sociales | C35: Dr. Diego Soto Hernández | D35: DEP | E35: 4
B37: DGE 111
B38: Gestión y Administración Pública Electrónico | C38: Dr. Joselito Fernández Tapia | D38: DEP | E38: 4
B39: Sistemas para la Toma de Decisiones en Gobierno Elcetrónico | C39: Dr. Jesús Cruz Ahuactzi | D39: LI | E39: 4
B40: Marco Juridico e Institucional de Gobierno Electrónico | C40: Dr. Oscar David Valencia López | D40: DEP | E40: 4
B41: Metodologia de la Investigación I | C41: Dr. Daniel Robles Torres | D41: DEP | E41: 4
B43: DGE 311
B44: Finanzas Públicas y Gobierno Electrónico | C44: Dr. Diego Soto Hernández | D44: DEP | E44: 4
B45: Aplicaciones Web y Móviles para Gobierno Electrónico | C45: Dra. Aidee Cruz Barragán | D45: LI | E45: 4
B46: Gestión de Proyectos Tecnológicos de Gobierno Electrónico | C46: Dr. Alejandro Jarillo Silva | D46: LI | E46: 4
...

Sheet Asignación-Profesor
B2: LCB | C2: Profesor@ | D2: Materias | E2: LCB | F2: LM | G2: LO | H2: LE | I2: LN | J2: LCE | K2: LI | L2: LAP | M2: LGDM | N2: LAM | O2: DEP | P2: Total alumnos | Q2: Total hrs sem | R2: Observaciones
B3: 1 | C3: M.B.E. Raúl Misael Cortés Olivera | D3: =SUM(E3:O3) -> 1 | E3: =COUNTIF(LCB!$C$4:$C$40,C3) -> 1 | F3: =COUNTIF(LM!$C$4:$C$144,C3) -> 0 | G3: =COUNTIF(LO!$C$4:$C$227,C3) -> 0 | H3: =COUNTIF(LE!$C$4:$C$214,C3) -> 0 | I3: =COUNTIF(LN!$C$4:$C$53,C3) -> 0 | J3: =COUNTIF(LCE!$C$3:$C$43,C3) -> 0 | K3: =COUNTIF(LI!$C$4:$C$60,C3) -> 0 | L3: =COUNTIF(LAP!$C$5:$C$45,C3) -> 0 | M3: =COUNTIF(LGDM!$C$4:$C$22,C3) -> 0 | N3: =COUNTIF(LAM!$C$5:$C$21,C3) -> 0 | O3: =COUNTIF(DEP!$C$3:$C$61,C3) -> 0 | P3: =SUMIF(LCB!$C$4:$C$45,C3,LCB!$F$4:$F$45)+SUMIF(LM!$C$4:$C$140,C3,LM!$F$4:$F$140)+SUMIF(LO!$C$4:$C$230,C3,LO!$F$4:$F$230)+SUMIF(LE!$C$4:$C$200,C3,LE!$F$4:$F$200)+SUMIF(LN!$C$4:$C$48,C3,LN!$F$4:$F$48)+SUMIF(LCE!$C$4:$C$40,C3,LCE!$F$4:$F$40)+SUMIF(LI!$C$4:$C$55,C3,LI!$F$4:$F$55)+SUMIF(LAP!$C$4:$C$45,C3,LAP!$F$4:$F$45)+SUMIF(LGDM!$C$4:$C$22,C3,LGDM!$F$4:$F$22)+SUMIF(LAM!$C$4:$C$18,C3,LAM!$F$4:$F$18)+SUMIF(DEP!$C$4:$C$55,C3,DEP!$F$4:$F$55) -> 0 | Q3: =SUMIF(LCB!$C$4:$C$45,C3,LCB!$E$4:$E$45)+SUMIF(LM!$C$4:$C$140,C3,LM!$E$4:$E$140)+SUMIF(LO!$C$4:$C$230,C3,LO!$E$4:$E$230)+SUMIF(LE!$C$4:$C$200,C3,LE!$E$4:$E$200)+SUMIF(LN!$C$4:$C$48,C3,LN!$E$4:$E$48)+SUMIF(LCE!$C$4:$C$40,C3,LCE!$E$4:$E$40)+SUMIF(LI!$C$4:$C$55,C3,LI!$E$4:$E$55)+SUMIF(LAP!$C$4:$C$45,C3,LAP!$E$4:$E$45)+SUMIF(LGDM!$C$4:$C$15,C3,LGDM!$E$4:$E$15)+SUMIF(LAM!$C$5:$C$18,C3,LAM!$E$5:$E$18)+SUMIF(DEP!$C$4:$C$55,C3,DEP!$E$4:$E$55) -> 6
B4: 2 | C4: M.C.C.A.R.B. Guilibaldo Gabriel Zurita Vásquez | D4: =SUM(E4:O4) -> 3 | E4: =COUNTIF(LCB!$C$4:$C$40,C4) -> 0 | F4: =COUNTIF(LM!$C$4:$C$144,C4) -> 3 | G4: =COUNTIF(LO!$C$4:$C$227,C4) -> 0 | H4: =COUNTIF(LE!$C$4:$C$214,C4) -> 0 | I4: =COUNTIF(LN!$C$4:$C$53,C4) -> 0 | J4: =COUNTIF(LCE!$C$3:$C$43,C4) -> 0 | K4: =COUNTIF(LI!$C$4:$C$60,C4) -> 0 | L4: =COUNTIF(LAP!$C$5:$C$45,C4) -> 0 | M4: =COUNTIF(LGDM!$C$4:$C$22,C4) -> 0 | N4: =COUNTIF(LAM!$C$5:$C$21,C4) -> 0 | O4: =COUNTIF(DEP!$C$3:$C$61,C4) -> 0 | P4: =SUMIF(LCB!$C$4:$C$45,C4,LCB!$F$4:$F$45)+SUMIF(LM!$C$4:$C$140,C4,LM!$F$4:$F$140)+SUMIF(LO!$C$4:$C$230,C4,LO!$F$4:$F$230)+SUMIF(LE!$C$4:$C$200,C4,LE!$F$4:$F$200)+SUMIF(LN!$C$4:$C$48,C4,LN!$F$4:$F$48)+SUMIF(LCE!$C$4:$C$40,C4,LCE!$F$4:$F$40)+SUMIF(LI!$C$4:$C$55,C4,LI!$F$4:$F$55)+SUMIF(LAP!$C$4:$C$45,C4,LAP!$F$4:$F$45)+SUMIF(LGDM!$C$4:$C$22,C4,LGDM!$F$4:$F$22)+SUMIF(LAM!$C$4:$C$18,C4,LAM!$F$4:$F$18)+SUMIF(DEP!$C$4:$C$55,C4,DEP!$F$4:$F$55) -> 126 | Q4: =SUMIF(LCB!$C$4:$C$45,C4,LCB!$E$4:$E$45)+SUMIF(LM!$C$4:$C$140,C4,LM!$E$4:$E$140)+SUMIF(LO!$C$4:$C$230,C4,LO!$E$4:$E$230)+SUMIF(LE!$C$4:$C$200,C4,LE!$E$4:$E$200)+SUMIF(LN!$C$4:$C$48,C4,LN!$E$4:$E$48)+SUMIF(LCE!$C$4:$C$40,C4,LCE!$E$4:$E$40)+SUMIF(LI!$C$4:$C$55,C4,LI!$E$4:$E$55)+SUMIF(LAP!$C$4:$C$45,C4,LAP!$E$4:$E$45)+SUMIF(LGDM!$C$4:$C$15,C4,LGDM!$E$4:$E$15)+SUMIF(LAM!$C$5:$C$18,C4,LAM!$E$5:$E$18)+SUMIF(DEP!$C$4:$C$55,C4,DEP!$E$4:$E$55) -> 18
B5: 3 | C5: M.C.I.B. Ericay Berenice Martínez Ramos | D5: =SUM(E5:O5) -> 4 | E5: =COUNTIF(LCB!$C$4:$C$40,C5) -> 1 | F5: =COUNTIF(LM!$C$4:$C$144,C5) -> 0 | G5: =COUNTIF(LO!$C$4:$C$227,C5) -> 0 | H5: =COUNTIF(LE!$C$4:$C$214,C5) -> 3 | I5: =COUNTIF(LN!$C$4:$C$53,C5) -> 0 | J5: =COUNTIF(LCE!$C$3:$C$43,C5) -> 0 | K5: =COUNTIF(LI!$C$4:$C$60,C5) -> 0 | L5: =COUNTIF(LAP!$C$5:$C$45,C5) -> 0 | M5: =COUNTIF(LGDM!$C$4:$C$22,C5) -> 0 | N5: =COUNTIF(LAM!$C$5:$C$21,C5) -> 0 | O5: =COUNTIF(DEP!$C$3:$C$61,C5) -> 0 | P5: =SUMIF(LCB!$C$4:$C$45,C5,LCB!$F$4:$F$45)+SUMIF(LM!$C$4:$C$140,C5,LM!$F$4:$F$140)+SUMIF(LO!$C$4:$C$230,C5,LO!$F$4:$F$230)+SUMIF(LE!$C$4:$C$200,C5,LE!$F$4:$F$200)+SUMIF(LN!$C$4:$C$48,C5,LN!$F$4:$F$48)+SUMIF(LCE!$C$4:$C$40,C5,LCE!$F$4:$F$40)+SUMIF(LI!$C$4:$C$55,C5,LI!$F$4:$F$55)+SUMIF(LAP!$C$4:$C$45,C5,LAP!$F$4:$F$45)+SUMIF(LGDM!$C$4:$C$22,C5,LGDM!$F$4:$F$22)+SUMIF(LAM!$C$4:$C$18,C5,LAM!$F$4:$F$18)+SUMIF(DEP!$C$4:$C$55,C5,DEP!$F$4:$F$55) -> 0 | Q5: =SUMIF(LCB!$C$4:$C$45,C5,LCB!$E$4:$E$45)+SUMIF(LM!$C$4:$C$140,C5,LM!$E$4:$E$140)+SUMIF(LO!$C$4:$C$230,C5,LO!$E$4:$E$230)+SUMIF(LE!$C$4:$C$200,C5,LE!$E$4:$E$200)+SUMIF(LN!$C$4:$C$48,C5,LN!$E$4:$E$48)+SUMIF(LCE!$C$4:$C$40,C5,LCE!$E$4:$E$40)+SUMIF(LI!$C$4:$C$55,C5,LI!$E$4:$E$55)+SUMIF(LAP!$C$4:$C$45,C5,LAP!$E$4:$E$45)+SUMIF(LGDM!$C$4:$C$15,C5,LGDM!$E$4:$E$15)+SUMIF(LAM!$C$5:$C$18,C5,LAM!$E$5:$E$18)+SUMIF(DEP!$C$4:$C$55,C5,DEP!$E$4:$E$55) -> 23
B6: 4 | C6: Dra. Claudia Chávez López | D6: =SUM(E6:O6) -> 4 | E6: =COUNTIF(LCB!$C$4:$C$40,C6) -> 2 | F6: =COUNTIF(LM!$C$4:$C$144,C6) -> 0 | G6: =COUNTIF(LO!$C$4:$C$227,C6) -> 2 | H6: =COUNTIF(LE!$C$4:$C$214,C6) -> 0 | I6: =COUNTIF(LN!$C$4:$C$53,C6) -> 0 | J6: =COUNTIF(LCE!$C$3:$C$43,C6) -> 0 | K6: =COUNTIF(LI!$C$4:$C$60,C6) -> 0 | L6: =COUNTIF(LAP!$C$5:$C$45,C6) -> 0 | M6: =COUNTIF(LGDM!$C$4:$C$22,C6) -> 0 | N6: =COUNTIF(LAM!$C$5:$C$21,C6) -> 0 | O6: =COUNTIF(DEP!$C$3:$C$61,C6) -> 0 | P6: =SUMIF(LCB!$C$4:$C$45,C6,LCB!$F$4:$F$45)+SUMIF(LM!$C$4:$C$140,C6,LM!$F$4:$F$140)+SUMIF(LO!$C$4:$C$230,C6,LO!$F$4:$F$230)+SUMIF(LE!$C$4:$C$200,C6,LE!$F$4:$F$200)+SUMIF(LN!$C$4:$C$48,C6,LN!$F$4:$F$48)+SUMIF(LCE!$C$4:$C$40,C6,LCE!$F$4:$F$40)+SUMIF(LI!$C$4:$C$55,C6,LI!$F$4:$F$55)+SUMIF(LAP!$C$4:$C$45,C6,LAP!$F$4:$F$45)+SUMIF(LGDM!$C$4:$C$22,C6,LGDM!$F$4:$F$22)+SUMIF(LAM!$C$4:$C$18,C6,LAM!$F$4:$F$18)+SUMIF(DEP!$C$4:$C$55,C6,DEP!$F$4:$F$55) -> 0 | Q6: =SUMIF(LCB!$C$4:$C$45,C6,LCB!$E$4:$E$45)+SUMIF(LM!$C$4:$C$140,C6,LM!$E$4:$E$140)+SUMIF(LO!$C$4:$C$230,C6,LO!$E$4:$E$230)+SUMIF(LE!$C$4:$C$200,C6,LE!$E$4:$E$200)+SUMIF(LN!$C$4:$C$48,C6,LN!$E$4:$E$48)+SUMIF(LCE!$C$4:$C$40,C6,LCE!$E$4:$E$40)+SUMIF(LI!$C$4:$C$55,C6,LI!$E$4:$E$55)+SUMIF(LAP!$C$4:$C$45,C6,LAP!$E$4:$E$45)+SUMIF(LGDM!$C$4:$C$15,C6,LGDM!$E$4:$E$15)+SUMIF(LAM!$C$5:$C$18,C6,LAM!$E$5:$E$18)+SUMIF(DEP!$C$4:$C$55,C6,DEP!$E$4:$E$55) -> 22
B7: 5 | C7: M.C. Andrea Itayetzzi Ortiz García | D7: =SUM(E7:O7) -> 4 | E7: =COUNTIF(LCB!$C$4:$C$40,C7) -> 0 | F7: =COUNTIF(LM!$C$4:$C$144,C7) -> 0 | G7: =COUNTIF(LO!$C$4:$C$227,C7) -> 3 | H7: =COUNTIF(LE!$C$4:$C$214,C7) -> 1 | I7: =COUNTIF(LN!$C$4:$C$53,C7) -> 0 | J7: =COUNTIF(LCE!$C$3:$C$43,C7) -> 0 | K7: =COUNTIF(LI!$C$4:$C$60,C7) -> 0 | L7: =COUNTIF(LAP!$C$5:$C$45,C7) -> 0 | M7: =COUNTIF(LGDM!$C$4:$C$22,C7) -> 0 | N7: =COUNTIF(LAM!$C$5:$C$21,C7) -> 0 | O7: =COUNTIF(DEP!$C$3:$C$61,C7) -> 0 | P7: =SUMIF(LCB!$C$4:$C$45,C7,LCB!$F$4:$F$45)+SUMIF(LM!$C$4:$C$140,C7,LM!$F$4:$F$140)+SUMIF(LO!$C$4:$C$230,C7,LO!$F$4:$F$230)+SUMIF(LE!$C$4:$C$200,C7,LE!$F$4:$F$200)+SUMIF(LN!$C$4:$C$48,C7,LN!$F$4:$F$48)+SUMIF(LCE!$C$4:$C$40,C7,LCE!$F$4:$F$40)+SUMIF(LI!$C$4:$C$55,C7,LI!$F$4:$F$55)+SUMIF(LAP!$C$4:$C$45,C7,LAP!$F$4:$F$45)+SUMIF(LGDM!$C$4:$C$22,C7,LGDM!$F$4:$F$22)+SUMIF(LAM!$C$4:$C$18,C7,LAM!$F$4:$F$18)+SUMIF(DEP!$C$4:$C$55,C7,DEP!$F$4:$F$55) -> 0 | Q7: =SUMIF(LCB!$C$4:$C$45,C7,LCB!$E$4:$E$45)+SUMIF(LM!$C$4:$C$140,C7,LM!$E$4:$E$140)+SUMIF(LO!$C$4:$C$230,C7,LO!$E$4:$E$230)+SUMIF(LE!$C$4:$C$200,C7,LE!$E$4:$E$200)+SUMIF(LN!$C$4:$C$48,C7,LN!$E$4:$E$48)+SUMIF(LCE!$C$4:$C$40,C7,LCE!$E$4:$E$40)+SUMIF(LI!$C$4:$C$55,C7,LI!$E$4:$E$55)+SUMIF(LAP!$C$4:$C$45,C7,LAP!$E$4:$E$45)+SUMIF(LGDM!$C$4:$C$15,C7,LGDM!$E$4:$E$15)+SUMIF(LAM!$C$5:$C$18,C7,LAM!$E$5:$E$18)+SUMIF(DEP!$C$4:$C$55,C7,DEP!$E$4:$E$55) -> 21
B8: 6 | C8: Dr. Abisaí Martínez Sánchez | D8: =SUM(E8:O8) -> 4 | E8: =COUNTIF(LCB!$C$4:$C$40,C8) -> 0 | F8: =COUNTIF(LM!$C$4:$C$144,C8) -> 0 | G8: =COUNTIF(LO!$C$4:$C$227,C8) -> 1 | H8: =COUNTIF(LE!$C$4:$C$214,C8) -> 3 | I8: =COUNTIF(LN!$C$4:$C$53,C8) -> 0 | J8: =COUNTIF(LCE!$C$3:$C$43,C8) -> 0 | K8: =COUNTIF(LI!$C$4:$C$60,C8) -> 0 | L8: =COUNTIF(LAP!$C$5:$C$45,C8) -> 0 | M8: =COUNTIF(LGDM!$C$4:$C$22,C8) -> 0 | N8: =COUNTIF(LAM!$C$5:$C$21,C8) -> 0 | O8: =COUNTIF(DEP!$C$3:$C$61,C8) -> 0 | P8: =SUMIF(LCB!$C$4:$C$45,C8,LCB!$F$4:$F$45)+SUMIF(LM!$C$4:$C$140,C8,LM!$F$4:$F$140)+SUMIF(LO!$C$4:$C$230,C8,LO!$F$4:$F$230)+SUMIF(LE!$C$4:$C$200,C8,LE!$F$4:$F$200)+SUMIF(LN!$C$4:$C$48,C8,LN!$F$4:$F$48)+SUMIF(LCE!$C$4:$C$40,C8,LCE!$F$4:$F$40)+SUMIF(LI!$C$4:$C$55,C8,LI!$F$4:$F$55)+SUMIF(LAP!$C$4:$C$45,C8,LAP!$F$4:$F$45)+SUMIF(LGDM!$C$4:$C$22,C8,LGDM!$F$4:$F$22)+SUMIF(LAM!$C$4:$C$18,C8,LAM!$F$4:$F$18)+SUMIF(DEP!$C$4:$C$55,C8,DEP!$F$4:$F$55) -> 0 | Q8: =SUMIF(LCB!$C$4:$C$45,C8,LCB!$E$4:$E$45)+SUMIF(LM!$C$4:$C$140,C8,LM!$E$4:$E$140)+SUMIF(LO!$C$4:$C$230,C8,LO!$E$4:$E$230)+SUMIF(LE!$C$4:$C$200,C8,LE!$E$4:$E$200)+SUMIF(LN!$C$4:$C$48,C8,LN!$E$4:$E$48)+SUMIF(LCE!$C$4:$C$40,C8,LCE!$E$4:$E$40)+SUMIF(LI!$C$4:$C$55,C8,LI!$E$4:$E$55)+SUMIF(LAP!$C$4:$C$45,C8,LAP!$E$4:$E$45)+SUMIF(LGDM!$C$4:$C$15,C8,LGDM!$E$4:$E$15)+SUMIF(LAM!$C$5:$C$18,C8,LAM!$E$5:$E$18)+SUMIF(DEP!$C$4:$C$55,C8,DEP!$E$4:$E$55) -> 23
B9: 7 | C9: Dra. Lilian Arzeta Pino | D9: =SUM(E9:O9) -> 4 | E9: =COUNTIF(LCB!$C$4:$C$40,C9) -> 0 | F9: =COUNTIF(LM!$C$4:$C$144,C9) -> 0 | G9: =COUNTIF(LO!$C$4:$C$227,C9) -> 1 | H9: =COUNTIF(LE!$C$4:$C$214,C9) -> 2 | I9: =COUNTIF(LN!$C$4:$C$53,C9) -> 0 | J9: =COUNTIF(LCE!$C$3:$C$43,C9) -> 0 | K9: =COUNTIF(LI!$C$4:$C$60,C9) -> 0 | L9: =COUNTIF(LAP!$C$5:$C$45,C9) -> 0 | M9: =COUNTIF(LGDM!$C$4:$C$22,C9) -> 0 | N9: =COUNTIF(LAM!$C$5:$C$21,C9) -> 0 | O9: =COUNTIF(DEP!$C$3:$C$61,C9) -> 1 | P9: =SUMIF(LCB!$C$4:$C$45,C9,LCB!$F$4:$F$45)+SUMIF(LM!$C$4:$C$140,C9,LM!$F$4:$F$140)+SUMIF(LO!$C$4:$C$230,C9,LO!$F$4:$F$230)+SUMIF(LE!$C$4:$C$200,C9,LE!$F$4:$F$200)+SUMIF(LN!$C$4:$C$48,C9,LN!$F$4:$F$48)+SUMIF(LCE!$C$4:$C$40,C9,LCE!$F$4:$F$40)+SUMIF(LI!$C$4:$C$55,C9,LI!$F$4:$F$55)+SUMIF(LAP!$C$4:$C$45,C9,LAP!$F$4:$F$45)+SUMIF(LGDM!$C$4:$C$22,C9,LGDM!$F$4:$F$22)+SUMIF(LAM!$C$4:$C$18,C9,LAM!$F$4:$F$18)+SUMIF(DEP!$C$4:$C$55,C9,DEP!$F$4:$F$55) -> 0 | Q9: =SUMIF(LCB!$C$4:$C$45,C9,LCB!$E$4:$E$45)+SUMIF(LM!$C$4:$C$140,C9,LM!$E$4:$E$140)+SUMIF(LO!$C$4:$C$230,C9,LO!$E$4:$E$230)+SUMIF(LE!$C$4:$C$200,C9,LE!$E$4:$E$200)+SUMIF(LN!$C$4:$C$48,C9,LN!$E$4:$E$48)+SUMIF(LCE!$C$4:$C$40,C9,LCE!$E$4:$E$40)+SUMIF(LI!$C$4:$C$55,C9,LI!$E$4:$E$55)+SUMIF(LAP!$C$4:$C$45,C9,LAP!$E$4:$E$45)+SUMIF(LGDM!$C$4:$C$15,C9,LGDM!$E$4:$E$15)+SUMIF(LAM!$C$5:$C$18,C9,LAM!$E$5:$E$18)+SUMIF(DEP!$C$4:$C$55,C9,DEP!$E$4:$E$55) -> 21
B10: 8 | C10: Dr. Edgar Rodrigo Guzmán Bautista | D10: =SUM(E10:O10) -> 2 | E10: =COUNTIF(LCB!$C$4:$C$40,C10) -> 2 | F10: =COUNTIF(LM!$C$4:$C$144,C10) -> 0 | G10: =COUNTIF(LO!$C$4:$C$227,C10) -> 0 | H10: =COUNTIF(LE!$C$4:$C$214,C10) -> 0 | I10: =COUNTIF(LN!$C$4:$C$53,C10) -> 0 | J10: =COUNTIF(LCE!$C$3:$C$43,C10) -> 0 | K10: =COUNTIF(LI!$C$4:$C$60,C10) -> 0 | L10: =COUNTIF(LAP!$C$5:$C$45,C10) -> 0 | M10: =COUNTIF(LGDM!$C$4:$C$22,C10) -> 0 | N10: =COUNTIF(LAM!$C$5:$C$21,C10) -> 0 | O10: =COUNTIF(DEP!$C$3:$C$61,C10) -> 0 | P10: =SUMIF(LCB!$C$4:$C$45,C10,LCB!$F$4:$F$45)+SUMIF(LM!$C$4:$C$140,C10,LM!$F$4:$F$140)+SUMIF(LO!$C$4:$C$230,C10,LO!$F$4:$F$230)+SUMIF(LE!$C$4:$C$200,C10,LE!$F$4:$F$200)+SUMIF(LN!$C$4:$C$48,C10,LN!$F$4:$F$48)+SUMIF(LCE!$C$4:$C$40,C10,LCE!$F$4:$F$40)+SUMIF(LI!$C$4:$C$55,C10,LI!$F$4:$F$55)+SUMIF(LAP!$C$4:$C$45,C10,LAP!$F$4:$F$45)+SUMIF(LGDM!$C$4:$C$22,C10,LGDM!$F$4:$F$22)+SUMIF(LAM!$C$4:$C$18,C10,LAM!$F$4:$F$18)+SUMIF(DEP!$C$4:$C$55,C10,DEP!$F$4:$F$55) -> 0 | Q10: =SUMIF(LCB!$C$4:$C$45,C10,LCB!$E$4:$E$45)+SUMIF(LM!$C$4:$C$140,C10,LM!$E$4:$E$140)+SUMIF(LO!$C$4:$C$230,C10,LO!$E$4:$E$230)+SUMIF(LE!$C$4:$C$200,C10,LE!$E$4:$E$200)+SUMIF(LN!$C$4:$C$48,C10,LN!$E$4:$E$48)+SUMIF(LCE!$C$4:$C$40,C10,LCE!$E$4:$E$40)+SUMIF(LI!$C$4:$C$55,C10,LI!$E$4:$E$55)+SUMIF(LAP!$C$4:$C$45,C10,LAP!$E$4:$E$45)+SUMIF(LGDM!$C$4:$C$15,C10,LGDM!$E$4:$E$15)+SUMIF(LAM!$C$5:$C$18,C10,LAM!$E$5:$E$18)+SUMIF(DEP!$C$4:$C$55,C10,DEP!$E$4:$E$55) -> 11
B11: 9 | C11: Dr. Juan Carlos Barragán Gálvez | D11: =SUM(E11:O11) -> 3 | E11: =COUNTIF(LCB!$C$4:$C$40,C11) -> 1 | F11: =COUNTIF(LM!$C$4:$C$144,C11) -> 2 | G11: =COUNTIF(LO!$C$4:$C$227,C11) -> 0 | H11: =COUNTIF(LE!$C$4:$C$214,C11) -> 0 | I11: =COUNTIF(LN!$C$4:$C$53,C11) -> 0 | J11: =COUNTIF(LCE!$C$3:$C$43,C11) -> 0 | K11: =COUNTIF(LI!$C$4:$C$60,C11) -> 0 | L11: =COUNTIF(LAP!$C$5:$C$45,C11) -> 0 | M11: =COUNTIF(LGDM!$C$4:$C$22,C11) -> 0 | N11: =COUNTIF(LAM!$C$5:$C$21,C11) -> 0 | O11: =COUNTIF(DEP!$C$3:$C$61,C11) -> 0 | P11: =SUMIF(LCB!$C$4:$C$45,C11,LCB!$F$4:$F$45)+SUMIF(LM!$C$4:$C$140,C11,LM!$F$4:$F$140)+SUMIF(LO!$C$4:$C$230,C11,LO!$F$4:$F$230)+SUMIF(LE!$C$4:$C$200,C11,LE!$F$4:$F$200)+SUMIF(LN!$C$4:$C$48,C11,LN!$F$4:$F$48)+SUMIF(LCE!$C$4:$C$40,C11,LCE!$F$4:$F$40)+SUMIF(LI!$C$4:$C$55,C11,LI!$F$4:$F$55)+SUMIF(LAP!$C$4:$C$45,C11,LAP!$F$4:$F$45)+SUMIF(LGDM!$C$4:$C$22,C11,LGDM!$F$4:$F$22)+SUMIF(LAM!$C$4:$C$18,C11,LAM!$F$4:$F$18)+SUMIF(DEP!$C$4:$C$55,C11,DEP!$F$4:$F$55) -> 70 | Q11: =SUMIF(LCB!$C$4:$C$45,C11,LCB!$E$4:$E$45)+SUMIF(LM!$C$4:$C$140,C11,LM!$E$4:$E$140)+SUMIF(LO!$C$4:$C$230,C11,LO!$E$4:$E$230)+SUMIF(LE!$C$4:$C$200,C11,LE!$E$4:$E$200)+SUMIF(LN!$C$4:$C$48,C11,LN!$E$4:$E$48)+SUMIF(LCE!$C$4:$C$40,C11,LCE!$E$4:$E$40)+SUMIF(LI!$C$4:$C$55,C11,LI!$E$4:$E$55)+SUMIF(LAP!$C$4:$C$45,C11,LAP!$E$4:$E$45)+SUMIF(LGDM!$C$4:$C$15,C11,LGDM!$E$4:$E$15)+SUMIF(LAM!$C$5:$C$18,C11,LAM!$E$5:$E$18)+SUMIF(DEP!$C$4:$C$55,C11,DEP!$E$4:$E$55) -> 18
B12: 10 | C12: Dra. Karla Esmeralda Tello Ortega | D12: =SUM(E12:O12) -> 3 | E12: =COUNTIF(LCB!$C$4:$C$40,C12) -> 1 | F12: =COUNTIF(LM!$C$4:$C$144,C12) -> 0 | G12: =COUNTIF(LO!$C$4:$C$227,C12) -> 0 | H12: =COUNTIF(LE!$C$4:$C$214,C12) -> 2 | I12: =COUNTIF(LN!$C$4:$C$53,C12) -> 0 | J12: =COUNTIF(LCE!$C$3:$C$43,C12) -> 0 | K12: =COUNTIF(LI!$C$4:$C$60,C12) -> 0 | L12: =COUNTIF(LAP!$C$5:$C$45,C12) -> 0 | M12: =COUNTIF(LGDM!$C$4:$C$22,C12) -> 0 | N12: =COUNTIF(LAM!$C$5:$C$21,C12) -> 0 | O12: =COUNTIF(DEP!$C$3:$C$61,C12) -> 0 | P12: =SUMIF(LCB!$C$4:$C$45,C12,LCB!$F$4:$F$45)+SUMIF(LM!$C$4:$C$140,C12,LM!$F$4:$F$140)+SUMIF(LO!$C$4:$C$230,C12,LO!$F$4:$F$230)+SUMIF(LE!$C$4:$C$200,C12,LE!$F$4:$F$200)+SUMIF(LN!$C$4:$C$48,C12,LN!$F$4:$F$48)+SUMIF(LCE!$C$4:$C$40,C12,LCE!$F$4:$F$40)+SUMIF(LI!$C$4:$C$55,C12,LI!$F$4:$F$55)+SUMIF(LAP!$C$4:$C$45,C12,LAP!$F$4:$F$45)+SUMIF(LGDM!$C$4:$C$22,C12,LGDM!$F$4:$F$22)+SUMIF(LAM!$C$4:$C$18,C12,LAM!$F$4:$F$18)+SUMIF(DEP!$C$4:$C$55,C12,DEP!$F$4:$F$55) -> 0 | Q12: =SUMIF(LCB!$C$4:$C$45,C12,LCB!$E$4:$E$45)+SUMIF(LM!$C$4:$C$140,C12,LM!$E$4:$E$140)+SUMIF(LO!$C$4:$C$230,C12,LO!$E$4:$E$230)+SUMIF(LE!$C$4:$C$200,C12,LE!$E$4:$E$200)+SUMIF(LN!$C$4:$C$48,C12,LN!$E$4:$E$48)+SUMIF(LCE!$C$4:$C$40,C12,LCE!$E$4:$E$40)+SUMIF(LI!$C$4:$C$55,C12,LI!$E$4:$E$55)+SUMIF(LAP!$C$4:$C$45,C12,LAP!$E$4:$E$45)+SUMIF(LGDM!$C$4:$C$15,C12,LGDM!$E$4:$E$15)+SUMIF(LAM!$C$5:$C$18,C12,LAM!$E$5:$E$18)+SUMIF(DEP!$C$4:$C$55,C12,DEP!$E$4:$E$55) -> 16
B13: 11 | C13: M.B.E. Diego Sait Cruz Hernández | D13: =SUM(E13:O13) -> 4 | E13: =COUNTIF(LCB!$C$4:$C$40,C13) -> 1 | F13: =COUNTIF(LM!$C$4:$C$144,C13) -> 0 | G13: =COUNTIF(LO!$C$4:$C$227,C13) -> 3 | H13: =COUNTIF(LE!$C$4:$C$214,C13) -> 0 | I13: =COUNTIF(LN!$C$4:$C$53,C13) -> 0 | J13: =COUNTIF(LCE!$C$3:$C$43,C13) -> 0 | K13: =COUNTIF(LI!$C$4:$C$60,C13) -> 0 | L13: =COUNTIF(LAP!$C$5:$C$45,C13) -> 0 | M13: =COUNTIF(LGDM!$C$4:$C$22,C13) -> 0 | N13: =COUNTIF(LAM!$C$5:$C$21,C13) -> 0 | O13: =COUNTIF(DEP!$C$3:$C$61,C13) -> 0 | P13: =SUMIF(LCB!$C$4:$C$45,C13,LCB!$F$4:$F$45)+SUMIF(LM!$C$4:$C$140,C13,LM!$F$4:$F$140)+SUMIF(LO!$C$4:$C$230,C13,LO!$F$4:$F$230)+SUMIF(LE!$C$4:$C$200,C13,LE!$F$4:$F$200)+SUMIF(LN!$C$4:$C$48,C13,LN!$F$4:$F$48)+SUMIF(LCE!$C$4:$C$40,C13,LCE!$F$4:$F$40)+SUMIF(LI!$C$4:$C$55,C13,LI!$F$4:$F$55)+SUMIF(LAP!$C$4:$C$45,C13,LAP!$F$4:$F$45)+SUMIF(LGDM!$C$4:$C$22,C13,LGDM!$F$4:$F$22)+SUMIF(LAM!$C$4:$C$18,C13,LAM!$F$4:$F$18)+SUMIF(DEP!$C$4:$C$55,C13,DEP!$F$4:$F$55) -> 80 | Q13: =SUMIF(LCB!$C$4:$C$45,C13,LCB!$E$4:$E$45)+SUMIF(LM!$C$4:$C$140,C13,LM!$E$4:$E$140)+SUMIF(LO!$C$4:$C$230,C13,LO!$E$4:$E$230)+SUMIF(LE!$C$4:$C$200,C13,LE!$E$4:$E$200)+SUMIF(LN!$C$4:$C$48,C13,LN!$E$4:$E$48)+SUMIF(LCE!$C$4:$C$40,C13,LCE!$E$4:$E$40)+SUMIF(LI!$C$4:$C$55,C13,LI!$E$4:$E$55)+SUMIF(LAP!$C$4:$C$45,C13,LAP!$E$4:$E$45)+SUMIF(LGDM!$C$4:$C$15,C13,LGDM!$E$4:$E$15)+SUMIF(LAM!$C$5:$C$18,C13,LAM!$E$5:$E$18)+SUMIF(DEP!$C$4:$C$55,C13,DEP!$E$4:$E$55) -> 19
